2025-08-08 23:55:03.224 WARNING (SyncWorker_0) [homeassistant.loader] We found a custom integration watchman which has not been tested by Home Assistant. This component might cause stability problems, be sure to disable it if you experience issues with Home Assistant
2025-08-08 23:55:03.227 WARNING (SyncWorker_0) [homeassistant.loader] We found a custom integration average which has not been tested by Home Assistant. This component might cause stability problems, be sure to disable it if you experience issues with Home Assistant
2025-08-08 23:55:03.229 WARNING (SyncWorker_0) [homeassistant.loader] We found a custom integration dwains_dashboard which has not been tested by Home Assistant. This component might cause stability problems, be sure to disable it if you experience issues with Home Assistant
2025-08-08 23:55:03.231 WARNING (SyncWorker_0) [homeassistant.loader] We found a custom integration ui_lovelace_minimalist which has not been tested by Home Assistant. This component might cause stability problems, be sure to disable it if you experience issues with Home Assistant
2025-08-08 23:55:03.233 WARNING (SyncWorker_0) [homeassistant.loader] We found a custom integration rainbird_cloud which has not been tested by Home Assistant. This component might cause stability problems, be sure to disable it if you experience issues with Home Assistant
2025-08-08 23:55:03.235 WARNING (SyncWorker_0) [homeassistant.loader] We found a custom integration browser_mod which has not been tested by Home Assistant. This component might cause stability problems, be sure to disable it if you experience issues with Home Assistant
2025-08-08 23:55:03.237 WARNING (SyncWorker_0) [homeassistant.loader] We found a custom integration hacs which has not been tested by Home Assistant. This component might cause stability problems, be sure to disable it if you experience issues with Home Assistant
2025-08-08 23:55:14.254 ERROR (ImportExecutor_0) [homeassistant.components.camera.img_util] Error loading libturbojpeg; Camera snapshot performance will be sub-optimal
Traceback (most recent call last):
  File "/usr/src/homeassistant/homeassistant/components/camera/img_util.py", line 93, in __init__
    TurboJPEGSingleton.__instance = TurboJPEG()
                                    ~~~~~~~~~^^
  File "/usr/local/lib/python3.13/site-packages/turbojpeg.py", line 300, in __init__
    turbo_jpeg = cdll.LoadLibrary(
        self.__find_turbojpeg() if lib_path is None else lib_path)
  File "/usr/local/lib/python3.13/ctypes/__init__.py", line 471, in LoadLibrary
    return self._dlltype(name)
           ~~~~~~~~~~~~~^^^^^^
  File "/usr/local/lib/python3.13/ctypes/__init__.py", line 390, in __init__
    self._handle = _dlopen(self._name, mode)
                   ~~~~~~~^^^^^^^^^^^^^^^^^^
OSError: Error loading shared library /usr/lib/libturbojpeg.so.0: Exec format error
2025-08-08 23:55:32.829 WARNING (MainThread) [homeassistant.util.loop] Detected blocking call to load_default_certs with args (<ssl.SSLContext object at 0x7f58ee0a70>, <Purpose.SERVER_AUTH: _ASN1Object(nid=129, shortname='serverAuth', longname='TLS Web Server Authentication', oid='1.3.6.1.5.5.7.3.1')>) inside the event loop by integration 'freebox' at homeassistant/components/freebox/__init__.py, line 22: await api.open(entry.data[CONF_HOST], entry.data[CONF_PORT]) (offender: /usr/local/lib/python3.13/ssl.py, line 722: context.load_default_certs(purpose)), please create a bug report at https://github.com/home-assistant/core/issues?q=is%3Aopen+is%3Aissue+label%3A%22integration%3A+freebox%22
For developers, please see https://developers.home-assistant.io/docs/asyncio_blocking_operations/#load_default_certs
Traceback (most recent call last):
  File "<frozen runpy>", line 198, in _run_module_as_main
  File "<frozen runpy>", line 88, in _run_code
  File "/usr/src/homeassistant/homeassistant/__main__.py", line 223, in <module>
    sys.exit(main())
  File "/usr/src/homeassistant/homeassistant/__main__.py", line 209, in main
    exit_code = runner.run(runtime_conf)
  File "/usr/src/homeassistant/homeassistant/runner.py", line 156, in run
    return loop.run_until_complete(setup_and_run_hass(runtime_config))
  File "/usr/local/lib/python3.13/asyncio/base_events.py", line 706, in run_until_complete
    self.run_forever()
  File "/usr/local/lib/python3.13/asyncio/base_events.py", line 677, in run_forever
    self._run_once()
  File "/usr/local/lib/python3.13/asyncio/base_events.py", line 2034, in _run_once
    handle._run()
  File "/usr/local/lib/python3.13/asyncio/events.py", line 89, in _run
    self._context.run(self._callback, *self._args)
  File "/usr/src/homeassistant/homeassistant/setup.py", line 170, in async_setup_component
    result = await _async_setup_component(hass, domain, config)
  File "/usr/src/homeassistant/homeassistant/setup.py", line 470, in _async_setup_component
    await asyncio.gather(
  File "/usr/src/homeassistant/homeassistant/setup.py", line 472, in <genexpr>
    create_eager_task(
  File "/usr/src/homeassistant/homeassistant/util/async_.py", line 44, in create_eager_task
    return Task(coro, loop=loop, name=name, eager_start=True)
  File "/usr/src/homeassistant/homeassistant/config_entries.py", line 894, in async_setup_locked
    await self.async_setup(hass, integration=integration)
  File "/usr/src/homeassistant/homeassistant/config_entries.py", line 660, in async_setup
    await self.__async_setup_with_context(hass, integration)
  File "/usr/src/homeassistant/homeassistant/config_entries.py", line 749, in __async_setup_with_context
    result = await component.async_setup_entry(hass, self)
  File "/usr/src/homeassistant/homeassistant/components/freebox/__init__.py", line 22, in async_setup_entry
    await api.open(entry.data[CONF_HOST], entry.data[CONF_PORT])

2025-08-08 23:55:32.839 WARNING (MainThread) [homeassistant.util.loop] Detected blocking call to set_default_verify_paths with args (<ssl.SSLContext object at 0x7f58ee0a70>,) inside the event loop by integration 'freebox' at homeassistant/components/freebox/__init__.py, line 22: await api.open(entry.data[CONF_HOST], entry.data[CONF_PORT]) (offender: /usr/local/lib/python3.13/ssl.py, line 534: self.set_default_verify_paths()), please create a bug report at https://github.com/home-assistant/core/issues?q=is%3Aopen+is%3Aissue+label%3A%22integration%3A+freebox%22
For developers, please see https://developers.home-assistant.io/docs/asyncio_blocking_operations/#set_default_verify_paths
Traceback (most recent call last):
  File "<frozen runpy>", line 198, in _run_module_as_main
  File "<frozen runpy>", line 88, in _run_code
  File "/usr/src/homeassistant/homeassistant/__main__.py", line 223, in <module>
    sys.exit(main())
  File "/usr/src/homeassistant/homeassistant/__main__.py", line 209, in main
    exit_code = runner.run(runtime_conf)
  File "/usr/src/homeassistant/homeassistant/runner.py", line 156, in run
    return loop.run_until_complete(setup_and_run_hass(runtime_config))
  File "/usr/local/lib/python3.13/asyncio/base_events.py", line 706, in run_until_complete
    self.run_forever()
  File "/usr/local/lib/python3.13/asyncio/base_events.py", line 677, in run_forever
    self._run_once()
  File "/usr/local/lib/python3.13/asyncio/base_events.py", line 2034, in _run_once
    handle._run()
  File "/usr/local/lib/python3.13/asyncio/events.py", line 89, in _run
    self._context.run(self._callback, *self._args)
  File "/usr/src/homeassistant/homeassistant/setup.py", line 170, in async_setup_component
    result = await _async_setup_component(hass, domain, config)
  File "/usr/src/homeassistant/homeassistant/setup.py", line 470, in _async_setup_component
    await asyncio.gather(
  File "/usr/src/homeassistant/homeassistant/setup.py", line 472, in <genexpr>
    create_eager_task(
  File "/usr/src/homeassistant/homeassistant/util/async_.py", line 44, in create_eager_task
    return Task(coro, loop=loop, name=name, eager_start=True)
  File "/usr/src/homeassistant/homeassistant/config_entries.py", line 894, in async_setup_locked
    await self.async_setup(hass, integration=integration)
  File "/usr/src/homeassistant/homeassistant/config_entries.py", line 660, in async_setup
    await self.__async_setup_with_context(hass, integration)
  File "/usr/src/homeassistant/homeassistant/config_entries.py", line 749, in __async_setup_with_context
    result = await component.async_setup_entry(hass, self)
  File "/usr/src/homeassistant/homeassistant/components/freebox/__init__.py", line 22, in async_setup_entry
    await api.open(entry.data[CONF_HOST], entry.data[CONF_PORT])

2025-08-08 23:55:33.058 WARNING (MainThread) [homeassistant.util.loop] Detected blocking call to load_verify_locations with args (<ssl.SSLContext object at 0x7f58ee0a70>,) inside the event loop by integration 'freebox' at homeassistant/components/freebox/__init__.py, line 22: await api.open(entry.data[CONF_HOST], entry.data[CONF_PORT]) (offender: /usr/local/lib/python3.13/site-packages/freebox_api/aiofreepybox.py, line 124: ssl_ctx.load_verify_locations(cafile=cert_path)), please create a bug report at https://github.com/home-assistant/core/issues?q=is%3Aopen+is%3Aissue+label%3A%22integration%3A+freebox%22
For developers, please see https://developers.home-assistant.io/docs/asyncio_blocking_operations/#load_verify_locations
Traceback (most recent call last):
  File "<frozen runpy>", line 198, in _run_module_as_main
  File "<frozen runpy>", line 88, in _run_code
  File "/usr/src/homeassistant/homeassistant/__main__.py", line 223, in <module>
    sys.exit(main())
  File "/usr/src/homeassistant/homeassistant/__main__.py", line 209, in main
    exit_code = runner.run(runtime_conf)
  File "/usr/src/homeassistant/homeassistant/runner.py", line 156, in run
    return loop.run_until_complete(setup_and_run_hass(runtime_config))
  File "/usr/local/lib/python3.13/asyncio/base_events.py", line 706, in run_until_complete
    self.run_forever()
  File "/usr/local/lib/python3.13/asyncio/base_events.py", line 677, in run_forever
    self._run_once()
  File "/usr/local/lib/python3.13/asyncio/base_events.py", line 2034, in _run_once
    handle._run()
  File "/usr/local/lib/python3.13/asyncio/events.py", line 89, in _run
    self._context.run(self._callback, *self._args)
  File "/usr/src/homeassistant/homeassistant/setup.py", line 170, in async_setup_component
    result = await _async_setup_component(hass, domain, config)
  File "/usr/src/homeassistant/homeassistant/setup.py", line 470, in _async_setup_component
    await asyncio.gather(
  File "/usr/src/homeassistant/homeassistant/setup.py", line 472, in <genexpr>
    create_eager_task(
  File "/usr/src/homeassistant/homeassistant/util/async_.py", line 44, in create_eager_task
    return Task(coro, loop=loop, name=name, eager_start=True)
  File "/usr/src/homeassistant/homeassistant/config_entries.py", line 894, in async_setup_locked
    await self.async_setup(hass, integration=integration)
  File "/usr/src/homeassistant/homeassistant/config_entries.py", line 660, in async_setup
    await self.__async_setup_with_context(hass, integration)
  File "/usr/src/homeassistant/homeassistant/config_entries.py", line 749, in __async_setup_with_context
    result = await component.async_setup_entry(hass, self)
  File "/usr/src/homeassistant/homeassistant/components/freebox/__init__.py", line 22, in async_setup_entry
    await api.open(entry.data[CONF_HOST], entry.data[CONF_PORT])

2025-08-08 23:55:33.085 WARNING (MainThread) [homeassistant.util.loop] Detected blocking call to open with args (PosixPath('/config/.storage/freebox/2y52zdio_fbxos_fr.conf'), 'r') inside the event loop by integration 'freebox' at homeassistant/components/freebox/__init__.py, line 22: await api.open(entry.data[CONF_HOST], entry.data[CONF_PORT]) (offender: /usr/local/lib/python3.13/site-packages/freebox_api/aiofreepybox.py, line 328: with open(token_file, "r") as f:), please create a bug report at https://github.com/home-assistant/core/issues?q=is%3Aopen+is%3Aissue+label%3A%22integration%3A+freebox%22
For developers, please see https://developers.home-assistant.io/docs/asyncio_blocking_operations/#open
Traceback (most recent call last):
  File "<frozen runpy>", line 198, in _run_module_as_main
  File "<frozen runpy>", line 88, in _run_code
  File "/usr/src/homeassistant/homeassistant/__main__.py", line 223, in <module>
    sys.exit(main())
  File "/usr/src/homeassistant/homeassistant/__main__.py", line 209, in main
    exit_code = runner.run(runtime_conf)
  File "/usr/src/homeassistant/homeassistant/runner.py", line 156, in run
    return loop.run_until_complete(setup_and_run_hass(runtime_config))
  File "/usr/local/lib/python3.13/asyncio/base_events.py", line 706, in run_until_complete
    self.run_forever()
  File "/usr/local/lib/python3.13/asyncio/base_events.py", line 677, in run_forever
    self._run_once()
  File "/usr/local/lib/python3.13/asyncio/base_events.py", line 2034, in _run_once
    handle._run()
  File "/usr/local/lib/python3.13/asyncio/events.py", line 89, in _run
    self._context.run(self._callback, *self._args)
  File "/usr/src/homeassistant/homeassistant/setup.py", line 170, in async_setup_component
    result = await _async_setup_component(hass, domain, config)
  File "/usr/src/homeassistant/homeassistant/setup.py", line 470, in _async_setup_component
    await asyncio.gather(
  File "/usr/src/homeassistant/homeassistant/setup.py", line 472, in <genexpr>
    create_eager_task(
  File "/usr/src/homeassistant/homeassistant/util/async_.py", line 44, in create_eager_task
    return Task(coro, loop=loop, name=name, eager_start=True)
  File "/usr/src/homeassistant/homeassistant/config_entries.py", line 894, in async_setup_locked
    await self.async_setup(hass, integration=integration)
  File "/usr/src/homeassistant/homeassistant/config_entries.py", line 660, in async_setup
    await self.__async_setup_with_context(hass, integration)
  File "/usr/src/homeassistant/homeassistant/config_entries.py", line 749, in __async_setup_with_context
    result = await component.async_setup_entry(hass, self)
  File "/usr/src/homeassistant/homeassistant/components/freebox/__init__.py", line 22, in async_setup_entry
    await api.open(entry.data[CONF_HOST], entry.data[CONF_PORT])

2025-08-08 23:55:34.299 ERROR (SyncWorker_0) [custom_components.dwains_dashboard.process_yaml] Unable to include file /config/dashboards/ios_premium/views/automations.yaml: [Errno 2] No such file or directory: '/config/dashboards/ios_premium/views/automations.yaml'
2025-08-08 23:55:35.175 WARNING (MainThread) [homeassistant.components.freebox.router] Home access is not granted
2025-08-08 23:55:46.205 WARNING (ImportExecutor_0) [py.warnings] /usr/local/lib/python3.13/site-packages/google/__init__.py:2: UserWarning: pkg_resources is deprecated as an API. See https://setuptools.pypa.io/en/latest/pkg_resources.html. The pkg_resources package is slated for removal as early as 2025-11-30. Refrain from using this package or pin to Setuptools<81.
  __import__('pkg_resources').declare_namespace(__name__)

2025-08-08 23:55:47.185 ERROR (SyncWorker_1) [aiodhcpwatcher] Cannot watch for dhcp packets without a functional packet filter: libpcap is not available. Cannot compile filter !
2025-08-08 23:56:06.129 ERROR (MainThread) [custom_components.dwains_dashboard.sensor] Dwains Dashboard version check failed ClientConnectorDNSError(ConnectionKey(host='dwains-dashboard.dwainscheeren.nl', port=443, is_ssl=True, ssl=True, proxy=None, proxy_auth=None, proxy_headers_hash=None), OSError(None, 'Timeout while contacting DNS servers'))
2025-08-08 23:56:39.707 INFO (MainThread) [backoff] Backing off fetch_events(...) for 0.6s (aiohttp.client_exceptions.ClientConnectorDNSError: Cannot connect to host ha101-1.overkiz.com:443 ssl:default [Timeout while contacting DNS servers])
2025-08-09 00:01:15.547 ERROR (SyncWorker_7) [custom_components.dwains_dashboard.process_yaml] Unable to include file /config/dashboards/ios_premium/views/automations.yaml: [Errno 2] No such file or directory: '/config/dashboards/ios_premium/views/automations.yaml'
2025-08-09 00:01:17.736 ERROR (SyncWorker_5) [custom_components.dwains_dashboard.process_yaml] Unable to include file /config/dashboards/ios_premium/views/automations.yaml: [Errno 2] No such file or directory: '/config/dashboards/ios_premium/views/automations.yaml'
2025-08-09 00:01:18.546 ERROR (SyncWorker_4) [custom_components.dwains_dashboard.process_yaml] Unable to include file /config/dashboards/ios_premium/views/automations.yaml: [Errno 2] No such file or directory: '/config/dashboards/ios_premium/views/automations.yaml'
2025-08-09 00:01:18.942 ERROR (SyncWorker_3) [custom_components.dwains_dashboard.process_yaml] Unable to include file /config/dashboards/ios_premium/views/automations.yaml: [Errno 2] No such file or directory: '/config/dashboards/ios_premium/views/automations.yaml'
2025-08-09 00:01:19.293 ERROR (SyncWorker_1) [custom_components.dwains_dashboard.process_yaml] Unable to include file /config/dashboards/ios_premium/views/automations.yaml: [Errno 2] No such file or directory: '/config/dashboards/ios_premium/views/automations.yaml'
2025-08-09 00:01:19.742 ERROR (SyncWorker_0) [custom_components.dwains_dashboard.process_yaml] Unable to include file /config/dashboards/ios_premium/views/automations.yaml: [Errno 2] No such file or directory: '/config/dashboards/ios_premium/views/automations.yaml'
2025-08-09 00:01:20.043 ERROR (SyncWorker_6) [custom_components.dwains_dashboard.process_yaml] Unable to include file /config/dashboards/ios_premium/views/automations.yaml: [Errno 2] No such file or directory: '/config/dashboards/ios_premium/views/automations.yaml'
2025-08-09 00:01:20.155 ERROR (SyncWorker_2) [custom_components.dwains_dashboard.process_yaml] Unable to include file /config/dashboards/ios_premium/views/automations.yaml: [Errno 2] No such file or directory: '/config/dashboards/ios_premium/views/automations.yaml'
2025-08-09 00:01:20.269 ERROR (SyncWorker_7) [custom_components.dwains_dashboard.process_yaml] Unable to include file /config/dashboards/ios_premium/views/automations.yaml: [Errno 2] No such file or directory: '/config/dashboards/ios_premium/views/automations.yaml'
2025-08-09 00:05:20.646 ERROR (SyncWorker_2) [custom_components.dwains_dashboard.process_yaml] Unable to include file /config/dashboards/ios_premium/views/automations.yaml: [Errno 2] No such file or directory: '/config/dashboards/ios_premium/views/automations.yaml'
2025-08-09 00:05:21.506 ERROR (SyncWorker_7) [custom_components.dwains_dashboard.process_yaml] Unable to include file /config/dashboards/ios_premium/views/automations.yaml: [Errno 2] No such file or directory: '/config/dashboards/ios_premium/views/automations.yaml'
2025-08-09 00:05:22.067 ERROR (SyncWorker_5) [custom_components.dwains_dashboard.process_yaml] Unable to include file /config/dashboards/ios_premium/views/automations.yaml: [Errno 2] No such file or directory: '/config/dashboards/ios_premium/views/automations.yaml'
2025-08-09 00:05:22.549 ERROR (SyncWorker_4) [custom_components.dwains_dashboard.process_yaml] Unable to include file /config/dashboards/ios_premium/views/automations.yaml: [Errno 2] No such file or directory: '/config/dashboards/ios_premium/views/automations.yaml'
2025-08-09 00:05:22.942 ERROR (SyncWorker_3) [custom_components.dwains_dashboard.process_yaml] Unable to include file /config/dashboards/ios_premium/views/automations.yaml: [Errno 2] No such file or directory: '/config/dashboards/ios_premium/views/automations.yaml'
2025-08-09 00:05:23.377 ERROR (SyncWorker_1) [custom_components.dwains_dashboard.process_yaml] Unable to include file /config/dashboards/ios_premium/views/automations.yaml: [Errno 2] No such file or directory: '/config/dashboards/ios_premium/views/automations.yaml'
2025-08-09 00:05:23.848 ERROR (SyncWorker_0) [custom_components.dwains_dashboard.process_yaml] Unable to include file /config/dashboards/ios_premium/views/automations.yaml: [Errno 2] No such file or directory: '/config/dashboards/ios_premium/views/automations.yaml'
2025-08-09 00:06:43.952 ERROR (SyncWorker_4) [custom_components.dwains_dashboard.process_yaml] Unable to include file /config/dashboards/ios_premium/views/automations.yaml: [Errno 2] No such file or directory: '/config/dashboards/ios_premium/views/automations.yaml'
